Workbook

Sheet Mapping
A1: Bamboo id | B1: salus id | C1: Name
A2: =bambooTrainingTypes!A2 -> 1154 | B2: =_xlfn.XLOOKUP(_xlfn.XLOOKUP(Mapping!A2,bambooTrainingTypes!A:A,bambooTrainingTypes!B:B),salusCertTypes!B:B,salusCertTypes!A:A) -> #N/A | C2: =_xlfn.XLOOKUP(Mapping!B2,salusCertTypes!A:A,salusCertTypes!B:B) -> #N/A
A3: =bambooTrainingTypes!A3 -> 1156 | B3: =_xlfn.XLOOKUP(_xlfn.XLOOKUP(Mapping!A3,bambooTrainingTypes!A:A,bambooTrainingTypes!B:B),salusCertTypes!B:B,salusCertTypes!A:A) -> 39453 | C3: =_xlfn.XLOOKUP(Mapping!B3,salusCertTypes!A:A,salusCertTypes!B:B) -> CPR/AED & First Aid
A4: =bambooTrainingTypes!A4 -> 1159 | B4: =_xlfn.XLOOKUP(_xlfn.XLOOKUP(Mapping!A4,bambooTrainingTypes!A:A,bambooTrainingTypes!B:B),salusCertTypes!B:B,salusCertTypes!A:A) -> 39471 | C4: =_xlfn.XLOOKUP(Mapping!B4,salusCertTypes!A:A,salusCertTypes!B:B) -> Roadway Worker Protection (RWP / Railroad)
A5: =bambooTrainingTypes!A5 -> 1209 | B5: =_xlfn.XLOOKUP(_xlfn.XLOOKUP(Mapping!A5,bambooTrainingTypes!A:A,bambooTrainingTypes!B:B),salusCertTypes!B:B,salusCertTypes!A:A) -> 39454 | C5: =_xlfn.XLOOKUP(Mapping!B5,salusCertTypes!A:A,salusCertTypes!B:B) -> Crisis Management
A6: =bambooTrainingTypes!A6 -> 1210 | B6: =_xlfn.XLOOKUP(_xlfn.XLOOKUP(Mapping!A6,bambooTrainingTypes!A:A,bambooTrainingTypes!B:B),salusCertTypes!B:B,salusCertTypes!A:A) -> 39483 | C6: =_xlfn.XLOOKUP(Mapping!B6,salusCertTypes!A:A,salusCertTypes!B:B) -> Job Hazard Analysis
A7: =bambooTrainingTypes!A7 -> 1211 | B7: =_xlfn.XLOOKUP(_xlfn.XLOOKUP(Mapping!A7,bambooTrainingTypes!A:A,bambooTrainingTypes!B:B),salusCertTypes!B:B,salusCertTypes!A:A) -> #N/A | C7: =_xlfn.XLOOKUP(Mapping!B7,salusCertTypes!A:A,salusCertTypes!B:B) -> #N/A
A8: =bambooTrainingTypes!A8 -> 1232 | B8: =_xlfn.XLOOKUP(_xlfn.XLOOKUP(Mapping!A8,bambooTrainingTypes!A:A,bambooTrainingTypes!B:B),salusCertTypes!B:B,salusCertTypes!A:A) -> #N/A | C8: =_xlfn.XLOOKUP(Mapping!B8,salusCertTypes!A:A,salusCertTypes!B:B) -> #N/A
A9: =bambooTrainingTypes!A9 -> 1233 | B9: =_xlfn.XLOOKUP(_xlfn.XLOOKUP(Mapping!A9,bambooTrainingTypes!A:A,bambooTrainingTypes!B:B),salusCertTypes!B:B,salusCertTypes!A:A) -> 39463 | C9: =_xlfn.XLOOKUP(Mapping!B9,salusCertTypes!A:A,salusCertTypes!B:B) -> Aerial Lifts Operator Certification
A10: =bambooTrainingTypes!A10 -> 1236 | B10: =_xlfn.XLOOKUP(_xlfn.XLOOKUP(Mapping!A10,bambooTrainingTypes!A:A,bambooTrainingTypes!B:B),salusCertTypes!B:B,salusCertTypes!A:A) -> #N/A | C10: =_xlfn.XLOOKUP(Mapping!B10,salusCertTypes!A:A,salusCertTypes!B:B) -> #N/A
A11: =bambooTrainingTypes!A11 -> 1237 | B11: =_xlfn.XLOOKUP(_xlfn.XLOOKUP(Mapping!A11,bambooTrainingTypes!A:A,bambooTrainingTypes!B:B),salusCertTypes!B:B,salusCertTypes!A:A) -> 39458 | C11: =_xlfn.XLOOKUP(Mapping!B11,salusCertTypes!A:A,salusCertTypes!B:B) -> Forklift Operator Certification
A12: =bambooTrainingTypes!A12 -> 1238 | B12: =_xlfn.XLOOKUP(_xlfn.XLOOKUP(Mapping!A12,bambooTrainingTypes!A:A,bambooTrainingTypes!B:B),salusCertTypes!B:B,salusCertTypes!A:A) -> #N/A | C12: =_xlfn.XLOOKUP(Mapping!B12,salusCertTypes!A:A,salusCertTypes!B:B) -> #N/A
A13: =bambooTrainingTypes!A13 -> 1240 | B13: =_xlfn.XLOOKUP(_xlfn.XLOOKUP(Mapping!A13,bambooTrainingTypes!A:A,bambooTrainingTypes!B:B),salusCertTypes!B:B,salusCertTypes!A:A) -> #N/A | C13: =_xlfn.XLOOKUP(Mapping!B13,salusCertTypes!A:A,salusCertTypes!B:B) -> #N/A
... A1635: =bambooTrainingTypes!A1635 -> 4417 | B1635: =_xlfn.XLOOKUP(_xlfn.XLOOKUP(Mapping!A1635,bambooTrainingTypes!A:A,bambooTrainingTypes!B:B),salusCertTypes!B:B,salusCertTypes!A:A) -> #N/A | C1635: =_xlfn.XLOOKUP(Mapping!B1635,salusCertTypes!A:A,salusCertTypes!B:B) -> #N/A

Sheet bambooTrainingTypes
A1: id | B1: name | C1: renewable | D1: frequency | E1: required | F1: categoryId | G1: categoryName | H1: dueFromHireDate | I1: allowEmployeesToMarkComplete | J1: linkUrl | K1: description
A2: 1154 | B2: Inactive: 10 Hour OSHA (retired version) | C2: FALSE | D2: 0 | E2: FALSE | F2: 19864 | G2: Safety | I2: FALSE | J2: https://stacywitbeck.myabsorb.com/admin/oauth/bamboohrssoauthentication?id=770d7f65-0291-4948-95ce-b831ca4e1236&courseId=4159c290-c715-4305-ae17-25ea0ca2f8a1 | K2: Online Course: OSHA 10-Hour Construction
A3: 1156 | B3: CPR/AED & First Aid | C3: TRUE | D3: 24 | E3: TRUE | F3: 19864 | G3: Safety | I3: FALSE
A4: 1159 | B4: Roadway Worker Protection (RWP / Railroad) | C4: TRUE | D4: 12 | E4: TRUE | F4: 19864 | G4: Safety | H4: 1 day | I4: FALSE
A5: 1209 | B5: Crisis Management | C5: FALSE | D5: 0 | E5: TRUE | F5: 19864 | G5: Safety | I5: FALSE
A6: 1210 | B6: Job Hazard Analysis | C6: FALSE | D6: 0 | E6: TRUE | F6: 19864 | G6: Safety | I6: FALSE
A7: 1211 | B7: Supervisor Drug and Alcohol Awareness (Reasonable Suspicion) | C7: FALSE | D7: 0 | E7: FALSE | F7: 19864 | G7: Safety | I7: FALSE | J7: https://stacywitbeck.myabsorb.com/admin/oauth/bamboohrssoauthentication?id=770d7f65-0291-4948-95ce-b831ca4e1236&courseId=9b9b083c-3658-4959-8de4-55157a7cee2c | K7: Online Course:
A8: 1232 | B8: Inactive: 8 Hour HAZWOPER Refresher (2022 Retired Version) | C8: FALSE | D8: 0 | E8: FALSE | F8: 19864 | G8: Safety | I8: FALSE | J8: https://stacywitbeck.myabsorb.com/admin/oauth/bamboohrssoauthentication?id=770d7f65-0291-4948-95ce-b831ca4e1236&courseId=f5030fb5-3270-4d75-a8dd-6f13066591ef | K8: Online Course: HAZWOPER 2019 Refresher (8-Hour)
A9: 1233 | B9: Aerial Lifts Operator Certification | C9: TRUE | D9: 36 | E9: FALSE | F9: 19864 | G9: Safety | I9: FALSE
A10: 1236 | B10: Flagger Certification or Training | C10: TRUE | D10: 36 | E10: FALSE | F10: 19864 | G10: Safety | I10: FALSE
A11: 1237 | B11: Forklift Operator Certification | C11: TRUE | D11: 36 | E11: FALSE | F11: 19864 | G11: Safety | I11: FALSE
A12: 1238 | B12: Respiratory Protection - Users | C12: TRUE | D12: 12 | E12: FALSE | F12: 19864 | G12: Safety | I12: FALSE
A13: 1240 | B13: Traffic Control Supervisor/Manager Certification | C13: TRUE | D13: 36 | E13: FALSE | F13: 19864 | G13: Safety | I13: FALSE
A14: 1241 | B14: Lead Awareness | C14: TRUE | D14: 12 | E14: FALSE | F14: 19864 | G14: Safety | I14: FALSE
A15: 1280 | B15: Heat Illness Prevention - Employees | C15: TRUE | D15: 12 | E15: FALSE | F15: 19864 | G15: Safety | I15: FALSE | J15: https://stacywitbeck.myabsorb.com/admin/oauth/bamboohrssoauthentication?id=770d7f65-0291-4948-95ce-b831ca4e1236&courseId=12679408-792d-4109-9114-0918538666c9 | K15: Online Course: Heat Stress / Heat Illness for Construction
A16: 1281 | B16: Heat Illness Prevention - Supervisors | C16: TRUE | D16: 12 | E16: FALSE | F16: 19864 | G16: Safety | I16: FALSE
A17: 1350 | B17: Traffic Control Maintainer Certification | C17: TRUE | D17: 36 | E17: FALSE | F17: 19864 | G17: Safety | I17: FALSE
A18: 1616 | B18: On Track Safety (Light Rail) | C18: TRUE | D18: 12 | E18: TRUE | F18: 19864 | G18: Safety | I18: FALSE
A19: 1617 | B19: Railroad Contractor Orientation | C19: TRUE | D19: 12 | E19: FALSE | F19: 19864 | G19: Safety | I19: FALSE
A20: 1619 | B20: Roadway Maintenance Machine Operator (RMM / Railroad) | C20: TRUE | D20: 12 | E20: FALSE | F20: 19864 | G20: Safety | I20: FALSE
A21: 1803 | B21: Crane Operator Certification (CCO) | C21: TRUE | D21: 60 | E21: FALSE | F21: 19864 | G21: Safety | I21: FALSE
A22: 1804 | B22: Supervisor Safety Orientation | C22: FALSE | D22: 0 | E22: TRUE | F22: 19864 | G22: Safety | H22: 1 day | I22: FALSE
A23: 1845 | B23: Power Tool Topic 01 - Chain Saws | C23: FALSE | D23: 0 | E23: FALSE | F23: 19864 | G23: Safety | I23: FALSE
A24: 1846 | B24: Power Tool Topic 02 - Cut-Off Saws | C24: FALSE | D24: 0 | E24: FALSE | F24: 19864 | G24: Safety | I24: FALSE
A25: 1847 | B25: Power Tool Topic 03 - Corded Saws | C25: FALSE | D25: 0 | E25: FALSE | F25: 19864 | G25: Safety | I25: FALSE
A26: 1848 | B26: Power Tool Topic 04 - Circular Saws | C26: FALSE | D26: 0 | E26: FALSE | F26: 19864 | G26: Safety | I26: FALSE
A27: 1850 | B27: Power Tool Topic 06 - Grinders | C27: FALSE | D27: 0 | E27: FALSE | F27: 19864 | G27: Safety | I27: FALSE
A28: 1851 | B28: Power Tool Topic 07 - Corded Drills | C28: FALSE | D28: 0 | E28: FALSE | F28: 19864 | G28: Safety | I28: FALSE
A29: 1852 | B29: Power Tool Topic 08 - Percussion Tools | C29: FALSE | D29: 0 | E29: FALSE | F29: 19864 | G29: Safety | I29: FALSE
A30: 1853 | B30: Power Tool Topic 09 - Generators | C30: FALSE | D30: 0 | E30: FALSE | F30: 19864 | G30: Safety | I30: FALSE
A31: 1854 | B31: Power Tool Topic 10 - Pneumatic (Air) Tools | C31: FALSE | D31: 0 | E31: FALSE | F31: 19864 | G31: Safety | I31: FALSE
A32: 1855 | B32: Power Tool Topic 11 - Nail Guns | C32: FALSE | D32: 0 | E32: FALSE | F32: 19864 | G32: Safety | I32: FALSE
A33: 1858 | B33: Power Tool Topic 14 - Cordless Tools | C33: FALSE | D33: 0 | E33: FALSE | F33: 19864 | G33: Safety | I33: FALSE
A34: 1859 | B34: Power Tool Topic 15 - Vibratory Rammers (Jumping Jacks) | C34: FALSE | D34: 0 | E34: FALSE | F34: 19864 | G34: Safety | I34: FALSE
... A37: 1865 | B37: Qualified Signal Person | C37: FALSE | D37: 0 | E37: FALSE | F37: 19864 | G37: Safety | I37: FALSE
A38: 1866 | B38: Inactive: 30 Hour OSHA (retired version) | C38: FALSE | D38: 0 | E38: FALSE | F38: 19864 | G38: Safety | I38: FALSE | J38: https://stacywitbeck.myabsorb.com/admin/oauth/bamboohrssoauthentication?id=770d7f65-0291-4948-95ce-b831ca4e1236&courseId=eff1871b-421d-41cc-881b-e88ebb2791d3 | K38: Online Course: OSHA 30-Hour Construction
A39: 1867 | B39: 40 Hour HAZWOPER | C39: FALSE | D39: 0 | E39: FALSE | F39: 19864 | G39: Safety | I39: FALSE | J39: https://stacywitbeck.myabsorb.com/admin/oauth/bamboohrssoauthentication?id=770d7f65-0291-4948-95ce-b831ca4e1236&courseId=d265d6bf-3cdd-4a3d-abd4-00006a800606 | K39: Online Course: HAZWOPER 40-Hour for All Industries
A40: 1868 | B40: Incident Investigation | C40: FALSE | D40: 0 | E40: FALSE | F40: 19864 | G40: Safety | I40: FALSE
A41: 1869 | B41: Confined Space Atmospheric Testing (Gas Detectors) | C41: FALSE | D41: 0 | E41: FALSE | F41: 19864 | G41: Safety | I41: FALSE
A42: 1870 | B42: Inactive: Bloodborne Pathogens (Click Safety) | C42: FALSE | D42: 0 | E42: FALSE | F42: 19864 | G42: Safety | I42: FALSE | J42: https://stacywitbeck.myabsorb.com/admin/oauth/bamboohrssoauthentication?id=770d7f65-0291-4948-95ce-b831ca4e1236&courseId=1ed12e63-92da-4278-abd3-5badb52cbebf | K42: Online Course: Bloodborne Pathogens for Construction
...

Sheet salusCertTypes
A1: id | B1: name | C1: required | D1: slug | E1: companyId
A2: 39453 | B2: CPR/AED & First Aid | C2: FALSE | D2: cpraed--first-aid | E2: 1246989 | F2: {=_xlfn.XLOOKUP(salusCertTypes!A2,Table1[[#All],[salus id]],Table1[[#All],[Name]])} -> CPR/AED & First Aid
A3: 39454 | B3: Crisis Management | C3: FALSE | D3: crisis-management | E3: 1246989 | F3: {=_xlfn.XLOOKUP(salusCertTypes!A3,Table1[[#All],[salus id]],Table1[[#All],[Name]])} -> Crisis Management
A4: 39456 | B4: 10 Hour OSHA | C4: FALSE | D4: 10-hour-osha | E4: 1246989 | F4: {=_xlfn.XLOOKUP(salusCertTypes!A4,Table1[[#All],[salus id]],Table1[[#All],[Name]])} -> 10 Hour OSHA
A5: 39457 | B5: Supervisor Safety Orientation | C5: FALSE | D5: supervisor-safety-orientation | E5: 1246989 | F5: {=_xlfn.XLOOKUP(salusCertTypes!A5,Table1[[#All],[salus id]],Table1[[#All],[Name]])} -> Supervisor Safety Orientation
A6: 39458 | B6: Forklift Operator Certification | C6: FALSE | D6: forklift-operator-certification | E6: 1246989 | F6: {=_xlfn.XLOOKUP(salusCertTypes!A6,Table1[[#All],[salus id]],Table1[[#All],[Name]])} -> Forklift Operator Certification
A7: 39459 | B7: Supervisor Drug and Alcohol Awareness (Reasonable Suspicion) Non-DOT | C7: FALSE | D7: supervisor-drug-and-alcohol-awareness-reasonable-suspicion-non-dot | E7: 1246989 | F7: {=_xlfn.XLOOKUP(salusCertTypes!A7,Table1[[#All],[salus id]],Table1[[#All],[Name]])} -> Supervisor Drug and Alcohol Awareness (Reasonable Suspicion) Non-DOT
A8: 39460 | B8: Safety Culture Excellence Workshop (SCEW) | C8: FALSE | D8: safety-culture-excellence-workshop-scew | E8: 1246989 | F8: {=_xlfn.XLOOKUP(salusCertTypes!A8,Table1[[#All],[salus id]],Table1[[#All],[Name]])} -> Safety Culture Excellence Workshop (SCEW)
A9: 39461 | B9: Risk Tolerance and Hazard Recognition | C9: FALSE | D9: risk-tolerance-and-hazard-recognition | E9: 1246989 | F9: {=_xlfn.XLOOKUP(salusCertTypes!A9,Table1[[#All],[salus id]],Table1[[#All],[Name]])} -> Risk Tolerance and Hazard Recognition
A10: 39462 | B10: STCKY Training (Sh!t That Can Kill You) | C10: FALSE | D10: stcky-training-sht-that-can-kill-you | E10: 1246989 | F10: {=_xlfn.XLOOKUP(salusCertTypes!A10,Table1[[#All],[salus id]],Table1[[#All],[Name]])} -> STCKY Training (Sh!t That Can Kill You)
A11: 39463 | B11: Aerial Lifts Operator Certification | C11: FALSE | D11: aerial-lifts-operator-certification | E11: 1246989 | F11: {=_xlfn.XLOOKUP(salusCertTypes!A11,Table1[[#All],[salus id]],Table1[[#All],[Name]])} -> Aerial Lifts Operator Certification
A12: 39464 | B12: Heat Illness Prevention - Supervisors | C12: FALSE | D12: heat-illness-prevention---supervisors | E12: 1246989 | F12: {=_xlfn.XLOOKUP(salusCertTypes!A12,Table1[[#All],[salus id]],Table1[[#All],[Name]])} -> Heat Illness Prevention - Supervisors
A13: 39465 | B13: Hearing Conservation | C13: FALSE | D13: hearing-conservation | E13: 1246989 | F13: {=_xlfn.XLOOKUP(salusCertTypes!A13,Table1[[#All],[salus id]],Table1[[#All],[Name]])} -> Hearing Conservation
... A45: 39498 | B45: Qualified Signal Person | C45: FALSE | D45: qualified-signal-person | E45: 1246989 | F45: {=_xlfn.XLOOKUP(salusCertTypes!A45,Table1[[#All],[salus id]],Table1[[#All],[Name]])} -> Qualified Signal Person
